{
 "cells": [
  {
   "cell_type": "code",
   "execution_count": null,
   "metadata": {},
   "outputs": [
    {
     "name": "stderr",
     "output_type": "stream",
     "text": [
      "ERROR:root:Internal Python error in the inspect module.\n",
      "Below is the traceback from this internal error.\n",
      "\n",
      "ERROR:root:Internal Python error in the inspect module.\n",
      "Below is the traceback from this internal error.\n",
      "\n",
      "ERROR:root:Internal Python error in the inspect module.\n",
      "Below is the traceback from this internal error.\n",
      "\n"
     ]
    },
    {
     "name": "stdout",
     "output_type": "stream",
     "text": [
      "Traceback (most recent call last):\n",
      "  File \"/Users/boerzhang/opt/anaconda3/lib/python3.8/site-packages/IPython/core/interactiveshell.py\", line 3343, in run_code\n",
      "    exec(code_obj, self.user_global_ns, self.user_ns)\n",
      "  File \"<ipython-input-21-e3fd803d8916>\", line 24, in <module>\n",
      "    mymark=Markov()\n",
      "  File \"<ipython-input-21-e3fd803d8916>\", line 4, in __init__\n",
      "    self.data = self.load_data()\n",
      "  File \"<ipython-input-21-e3fd803d8916>\", line 8, in load_data\n",
      "    return np.genfromtxt(file_path,delimiter=\",\")\n",
      "  File \"/Users/boerzhang/opt/anaconda3/lib/python3.8/site-packages/numpy/lib/npyio.py\", line 1749, in genfromtxt\n",
      "    fid = np.lib._datasource.open(fname, 'rt', encoding=encoding)\n",
      "  File \"/Users/boerzhang/opt/anaconda3/lib/python3.8/site-packages/numpy/lib/_datasource.py\", line 194, in open\n",
      "    ds = DataSource(destpath)\n",
      "  File \"/Users/boerzhang/opt/anaconda3/lib/python3.8/site-packages/numpy/lib/_datasource.py\", line 251, in __init__\n",
      "    self._destpath = os.path.abspath(destpath)\n",
      "  File \"/Users/boerzhang/opt/anaconda3/lib/python3.8/posixpath.py\", line 379, in abspath\n",
      "    cwd = os.getcwd()\n",
      "FileNotFoundError: [Errno 2] No such file or directory\n",
      "\n",
      "During handling of the above exception, another exception occurred:\n",
      "\n",
      "Traceback (most recent call last):\n",
      "  File \"/Users/boerzhang/opt/anaconda3/lib/python3.8/site-packages/IPython/core/interactiveshell.py\", line 2044, in showtraceback\n",
      "    stb = value._render_traceback_()\n",
      "AttributeError: 'FileNotFoundError' object has no attribute '_render_traceback_'\n",
      "\n",
      "During handling of the above exception, another exception occurred:\n",
      "\n",
      "Traceback (most recent call last):\n",
      "  File \"/Users/boerzhang/opt/anaconda3/lib/python3.8/site-packages/IPython/core/ultratb.py\", line 1169, in get_records\n",
      "    return _fixed_getinnerframes(etb, number_of_lines_of_context, tb_offset)\n",
      "  File \"/Users/boerzhang/opt/anaconda3/lib/python3.8/site-packages/IPython/core/ultratb.py\", line 316, in wrapped\n",
      "    return f(*args, **kwargs)\n",
      "  File \"/Users/boerzhang/opt/anaconda3/lib/python3.8/site-packages/IPython/core/ultratb.py\", line 350, in _fixed_getinnerframes\n",
      "    records = fix_frame_records_filenames(inspect.getinnerframes(etb, context))\n",
      "  File \"/Users/boerzhang/opt/anaconda3/lib/python3.8/inspect.py\", line 1503, in getinnerframes\n",
      "    frameinfo = (tb.tb_frame,) + getframeinfo(tb, context)\n",
      "  File \"/Users/boerzhang/opt/anaconda3/lib/python3.8/inspect.py\", line 1461, in getframeinfo\n",
      "    filename = getsourcefile(frame) or getfile(frame)\n",
      "  File \"/Users/boerzhang/opt/anaconda3/lib/python3.8/inspect.py\", line 708, in getsourcefile\n",
      "    if getattr(getmodule(object, filename), '__loader__', None) is not None:\n",
      "  File \"/Users/boerzhang/opt/anaconda3/lib/python3.8/inspect.py\", line 737, in getmodule\n",
      "    file = getabsfile(object, _filename)\n",
      "  File \"/Users/boerzhang/opt/anaconda3/lib/python3.8/inspect.py\", line 721, in getabsfile\n",
      "    return os.path.normcase(os.path.abspath(_filename))\n",
      "  File \"/Users/boerzhang/opt/anaconda3/lib/python3.8/posixpath.py\", line 379, in abspath\n",
      "    cwd = os.getcwd()\n",
      "FileNotFoundError: [Errno 2] No such file or directory\n",
      "Traceback (most recent call last):\n",
      "  File \"/Users/boerzhang/opt/anaconda3/lib/python3.8/site-packages/IPython/core/interactiveshell.py\", line 3343, in run_code\n",
      "    exec(code_obj, self.user_global_ns, self.user_ns)\n",
      "  File \"<ipython-input-21-e3fd803d8916>\", line 24, in <module>\n",
      "    mymark=Markov()\n",
      "  File \"<ipython-input-21-e3fd803d8916>\", line 4, in __init__\n",
      "    self.data = self.load_data()\n",
      "  File \"<ipython-input-21-e3fd803d8916>\", line 8, in load_data\n",
      "    return np.genfromtxt(file_path,delimiter=\",\")\n",
      "  File \"/Users/boerzhang/opt/anaconda3/lib/python3.8/site-packages/numpy/lib/npyio.py\", line 1749, in genfromtxt\n",
      "    fid = np.lib._datasource.open(fname, 'rt', encoding=encoding)\n",
      "  File \"/Users/boerzhang/opt/anaconda3/lib/python3.8/site-packages/numpy/lib/_datasource.py\", line 194, in open\n",
      "    ds = DataSource(destpath)\n",
      "  File \"/Users/boerzhang/opt/anaconda3/lib/python3.8/site-packages/numpy/lib/_datasource.py\", line 251, in __init__\n",
      "    self._destpath = os.path.abspath(destpath)\n",
      "  File \"/Users/boerzhang/opt/anaconda3/lib/python3.8/posixpath.py\", line 379, in abspath\n",
      "    cwd = os.getcwd()\n",
      "FileNotFoundError: [Errno 2] No such file or directory\n",
      "\n",
      "During handling of the above exception, another exception occurred:\n",
      "\n",
      "Traceback (most recent call last):\n",
      "  File \"/Users/boerzhang/opt/anaconda3/lib/python3.8/site-packages/IPython/core/interactiveshell.py\", line 2044, in showtraceback\n",
      "    stb = value._render_traceback_()\n",
      "AttributeError: 'FileNotFoundError' object has no attribute '_render_traceback_'\n",
      "\n",
      "During handling of the above exception, another exception occurred:\n",
      "\n",
      "Traceback (most recent call last):\n",
      "  File \"/Users/boerzhang/opt/anaconda3/lib/python3.8/site-packages/IPython/core/interactiveshell.py\", line 3263, in run_ast_nodes\n",
      "    if (await self.run_code(code, result,  async_=asy)):\n",
      "  File \"/Users/boerzhang/opt/anaconda3/lib/python3.8/site-packages/IPython/core/interactiveshell.py\", line 3360, in run_code\n",
      "    self.showtraceback(running_compiled_code=True)\n",
      "  File \"/Users/boerzhang/opt/anaconda3/lib/python3.8/site-packages/IPython/core/interactiveshell.py\", line 2046, in showtraceback\n",
      "    stb = self.InteractiveTB.structured_traceback(etype,\n",
      "  File \"/Users/boerzhang/opt/anaconda3/lib/python3.8/site-packages/IPython/core/ultratb.py\", line 1435, in structured_traceback\n",
      "    return FormattedTB.structured_traceback(\n",
      "  File \"/Users/boerzhang/opt/anaconda3/lib/python3.8/site-packages/IPython/core/ultratb.py\", line 1335, in structured_traceback\n",
      "    return VerboseTB.structured_traceback(\n",
      "  File \"/Users/boerzhang/opt/anaconda3/lib/python3.8/site-packages/IPython/core/ultratb.py\", line 1192, in structured_traceback\n",
      "    formatted_exception = self.format_exception_as_a_whole(etype, evalue, etb, number_of_lines_of_context,\n",
      "  File \"/Users/boerzhang/opt/anaconda3/lib/python3.8/site-packages/IPython/core/ultratb.py\", line 1150, in format_exception_as_a_whole\n",
      "    last_unique, recursion_repeat = find_recursion(orig_etype, evalue, records)\n",
      "  File \"/Users/boerzhang/opt/anaconda3/lib/python3.8/site-packages/IPython/core/ultratb.py\", line 451, in find_recursion\n",
      "    return len(records), 0\n",
      "TypeError: object of type 'NoneType' has no len()\n",
      "\n",
      "During handling of the above exception, another exception occurred:\n",
      "\n",
      "Traceback (most recent call last):\n",
      "  File \"/Users/boerzhang/opt/anaconda3/lib/python3.8/site-packages/IPython/core/interactiveshell.py\", line 2044, in showtraceback\n",
      "    stb = value._render_traceback_()\n",
      "AttributeError: 'TypeError' object has no attribute '_render_traceback_'\n",
      "\n",
      "During handling of the above exception, another exception occurred:\n",
      "\n",
      "Traceback (most recent call last):\n",
      "  File \"/Users/boerzhang/opt/anaconda3/lib/python3.8/site-packages/IPython/core/ultratb.py\", line 1169, in get_records\n",
      "    return _fixed_getinnerframes(etb, number_of_lines_of_context, tb_offset)\n",
      "  File \"/Users/boerzhang/opt/anaconda3/lib/python3.8/site-packages/IPython/core/ultratb.py\", line 316, in wrapped\n",
      "    return f(*args, **kwargs)\n",
      "  File \"/Users/boerzhang/opt/anaconda3/lib/python3.8/site-packages/IPython/core/ultratb.py\", line 350, in _fixed_getinnerframes\n",
      "    records = fix_frame_records_filenames(inspect.getinnerframes(etb, context))\n",
      "  File \"/Users/boerzhang/opt/anaconda3/lib/python3.8/inspect.py\", line 1503, in getinnerframes\n",
      "    frameinfo = (tb.tb_frame,) + getframeinfo(tb, context)\n",
      "  File \"/Users/boerzhang/opt/anaconda3/lib/python3.8/inspect.py\", line 1461, in getframeinfo\n",
      "    filename = getsourcefile(frame) or getfile(frame)\n",
      "  File \"/Users/boerzhang/opt/anaconda3/lib/python3.8/inspect.py\", line 708, in getsourcefile\n",
      "    if getattr(getmodule(object, filename), '__loader__', None) is not None:\n",
      "  File \"/Users/boerzhang/opt/anaconda3/lib/python3.8/inspect.py\", line 737, in getmodule\n",
      "    file = getabsfile(object, _filename)\n",
      "  File \"/Users/boerzhang/opt/anaconda3/lib/python3.8/inspect.py\", line 721, in getabsfile\n",
      "    return os.path.normcase(os.path.abspath(_filename))\n",
      "  File \"/Users/boerzhang/opt/anaconda3/lib/python3.8/posixpath.py\", line 379, in abspath\n",
      "    cwd = os.getcwd()\n",
      "FileNotFoundError: [Errno 2] No such file or directory\n",
      "Traceback (most recent call last):\n",
      "  File \"/Users/boerzhang/opt/anaconda3/lib/python3.8/site-packages/IPython/core/interactiveshell.py\", line 3343, in run_code\n",
      "    exec(code_obj, self.user_global_ns, self.user_ns)\n",
      "  File \"<ipython-input-21-e3fd803d8916>\", line 24, in <module>\n",
      "    mymark=Markov()\n",
      "  File \"<ipython-input-21-e3fd803d8916>\", line 4, in __init__\n",
      "    self.data = self.load_data()\n",
      "  File \"<ipython-input-21-e3fd803d8916>\", line 8, in load_data\n",
      "    return np.genfromtxt(file_path,delimiter=\",\")\n",
      "  File \"/Users/boerzhang/opt/anaconda3/lib/python3.8/site-packages/numpy/lib/npyio.py\", line 1749, in genfromtxt\n",
      "    fid = np.lib._datasource.open(fname, 'rt', encoding=encoding)\n",
      "  File \"/Users/boerzhang/opt/anaconda3/lib/python3.8/site-packages/numpy/lib/_datasource.py\", line 194, in open\n",
      "    ds = DataSource(destpath)\n",
      "  File \"/Users/boerzhang/opt/anaconda3/lib/python3.8/site-packages/numpy/lib/_datasource.py\", line 251, in __init__\n",
      "    self._destpath = os.path.abspath(destpath)\n",
      "  File \"/Users/boerzhang/opt/anaconda3/lib/python3.8/posixpath.py\", line 379, in abspath\n",
      "    cwd = os.getcwd()\n",
      "FileNotFoundError: [Errno 2] No such file or directory\n",
      "\n",
      "During handling of the above exception, another exception occurred:\n",
      "\n",
      "Traceback (most recent call last):\n",
      "  File \"/Users/boerzhang/opt/anaconda3/lib/python3.8/site-packages/IPython/core/interactiveshell.py\", line 2044, in showtraceback\n",
      "    stb = value._render_traceback_()\n",
      "AttributeError: 'FileNotFoundError' object has no attribute '_render_traceback_'\n",
      "\n",
      "During handling of the above exception, another exception occurred:\n",
      "\n",
      "Traceback (most recent call last):\n",
      "  File \"/Users/boerzhang/opt/anaconda3/lib/python3.8/site-packages/IPython/core/interactiveshell.py\", line 3263, in run_ast_nodes\n",
      "    if (await self.run_code(code, result,  async_=asy)):\n",
      "  File \"/Users/boerzhang/opt/anaconda3/lib/python3.8/site-packages/IPython/core/interactiveshell.py\", line 3360, in run_code\n",
      "    self.showtraceback(running_compiled_code=True)\n",
      "  File \"/Users/boerzhang/opt/anaconda3/lib/python3.8/site-packages/IPython/core/interactiveshell.py\", line 2046, in showtraceback\n",
      "    stb = self.InteractiveTB.structured_traceback(etype,\n",
      "  File \"/Users/boerzhang/opt/anaconda3/lib/python3.8/site-packages/IPython/core/ultratb.py\", line 1435, in structured_traceback\n",
      "    return FormattedTB.structured_traceback(\n",
      "  File \"/Users/boerzhang/opt/anaconda3/lib/python3.8/site-packages/IPython/core/ultratb.py\", line 1335, in structured_traceback\n",
      "    return VerboseTB.structured_traceback(\n",
      "  File \"/Users/boerzhang/opt/anaconda3/lib/python3.8/site-packages/IPython/core/ultratb.py\", line 1192, in structured_traceback\n",
      "    formatted_exception = self.format_exception_as_a_whole(etype, evalue, etb, number_of_lines_of_context,\n",
      "  File \"/Users/boerzhang/opt/anaconda3/lib/python3.8/site-packages/IPython/core/ultratb.py\", line 1150, in format_exception_as_a_whole\n",
      "    last_unique, recursion_repeat = find_recursion(orig_etype, evalue, records)\n",
      "  File \"/Users/boerzhang/opt/anaconda3/lib/python3.8/site-packages/IPython/core/ultratb.py\", line 451, in find_recursion\n",
      "    return len(records), 0\n",
      "TypeError: object of type 'NoneType' has no len()\n",
      "\n",
      "During handling of the above exception, another exception occurred:\n",
      "\n",
      "Traceback (most recent call last):\n",
      "  File \"/Users/boerzhang/opt/anaconda3/lib/python3.8/site-packages/IPython/core/interactiveshell.py\", line 2044, in showtraceback\n",
      "    stb = value._render_traceback_()\n",
      "AttributeError: 'TypeError' object has no attribute '_render_traceback_'\n",
      "\n",
      "During handling of the above exception, another exception occurred:\n",
      "\n",
      "Traceback (most recent call last):\n",
      "  File \"/Users/boerzhang/opt/anaconda3/lib/python3.8/site-packages/IPython/core/interactiveshell.py\", line 2895, in _run_cell\n",
      "    return runner(coro)\n",
      "  File \"/Users/boerzhang/opt/anaconda3/lib/python3.8/site-packages/IPython/core/async_helpers.py\", line 68, in _pseudo_sync_runner\n",
      "    coro.send(None)\n",
      "  File \"/Users/boerzhang/opt/anaconda3/lib/python3.8/site-packages/IPython/core/interactiveshell.py\", line 3071, in run_cell_async\n",
      "    has_raised = await self.run_ast_nodes(code_ast.body, cell_name,\n",
      "  File \"/Users/boerzhang/opt/anaconda3/lib/python3.8/site-packages/IPython/core/interactiveshell.py\", line 3282, in run_ast_nodes\n",
      "    self.showtraceback()\n",
      "  File \"/Users/boerzhang/opt/anaconda3/lib/python3.8/site-packages/IPython/core/interactiveshell.py\", line 2046, in showtraceback\n",
      "    stb = self.InteractiveTB.structured_traceback(etype,\n",
      "  File \"/Users/boerzhang/opt/anaconda3/lib/python3.8/site-packages/IPython/core/ultratb.py\", line 1435, in structured_traceback\n",
      "    return FormattedTB.structured_traceback(\n",
      "  File \"/Users/boerzhang/opt/anaconda3/lib/python3.8/site-packages/IPython/core/ultratb.py\", line 1335, in structured_traceback\n",
      "    return VerboseTB.structured_traceback(\n",
      "  File \"/Users/boerzhang/opt/anaconda3/lib/python3.8/site-packages/IPython/core/ultratb.py\", line 1210, in structured_traceback\n",
      "    formatted_exceptions += self.format_exception_as_a_whole(etype, evalue, etb, lines_of_context,\n",
      "  File \"/Users/boerzhang/opt/anaconda3/lib/python3.8/site-packages/IPython/core/ultratb.py\", line 1150, in format_exception_as_a_whole\n",
      "    last_unique, recursion_repeat = find_recursion(orig_etype, evalue, records)\n",
      "  File \"/Users/boerzhang/opt/anaconda3/lib/python3.8/site-packages/IPython/core/ultratb.py\", line 451, in find_recursion\n",
      "    return len(records), 0\n",
      "TypeError: object of type 'NoneType' has no len()\n",
      "\n",
      "During handling of the above exception, another exception occurred:\n",
      "\n",
      "Traceback (most recent call last):\n",
      "  File \"/Users/boerzhang/opt/anaconda3/lib/python3.8/site-packages/IPython/core/interactiveshell.py\", line 2044, in showtraceback\n",
      "    stb = value._render_traceback_()\n",
      "AttributeError: 'TypeError' object has no attribute '_render_traceback_'\n",
      "\n",
      "During handling of the above exception, another exception occurred:\n",
      "\n",
      "Traceback (most recent call last):\n",
      "  File \"/Users/boerzhang/opt/anaconda3/lib/python3.8/site-packages/IPython/core/ultratb.py\", line 1169, in get_records\n",
      "    return _fixed_getinnerframes(etb, number_of_lines_of_context, tb_offset)\n",
      "  File \"/Users/boerzhang/opt/anaconda3/lib/python3.8/site-packages/IPython/core/ultratb.py\", line 316, in wrapped\n",
      "    return f(*args, **kwargs)\n",
      "  File \"/Users/boerzhang/opt/anaconda3/lib/python3.8/site-packages/IPython/core/ultratb.py\", line 350, in _fixed_getinnerframes\n",
      "    records = fix_frame_records_filenames(inspect.getinnerframes(etb, context))\n",
      "  File \"/Users/boerzhang/opt/anaconda3/lib/python3.8/inspect.py\", line 1503, in getinnerframes\n",
      "    frameinfo = (tb.tb_frame,) + getframeinfo(tb, context)\n",
      "  File \"/Users/boerzhang/opt/anaconda3/lib/python3.8/inspect.py\", line 1461, in getframeinfo\n",
      "    filename = getsourcefile(frame) or getfile(frame)\n",
      "  File \"/Users/boerzhang/opt/anaconda3/lib/python3.8/inspect.py\", line 708, in getsourcefile\n",
      "    if getattr(getmodule(object, filename), '__loader__', None) is not None:\n",
      "  File \"/Users/boerzhang/opt/anaconda3/lib/python3.8/inspect.py\", line 737, in getmodule\n",
      "    file = getabsfile(object, _filename)\n",
      "  File \"/Users/boerzhang/opt/anaconda3/lib/python3.8/inspect.py\", line 721, in getabsfile\n",
      "    return os.path.normcase(os.path.abspath(_filename))\n",
      "  File \"/Users/boerzhang/opt/anaconda3/lib/python3.8/posixpath.py\", line 379, in abspath\n",
      "    cwd = os.getcwd()\n",
      "FileNotFoundError: [Errno 2] No such file or directory\n"
     ]
    }
   ],
   "source": [
    "import numpy as np\n",
    "class Markov:\n",
    "    def __init__(self): # You will need to modify this header line later in Part C\n",
    "        self.data = self.load_data()\n",
    "        \n",
    "\n",
    "    def load_data(self, file_path='./weather.csv'):\n",
    "        return np.genfromtxt(file_path,delimiter=\",\")\n",
    "\n",
    "    def get_prob(self, current_day_weather, next_day_weather): \n",
    "        cweather_num=np.nan\n",
    "        weather_array=np.array(['sunny','cloudy','rainy','snowy','windy','hailing'])\n",
    "        print(weather_array[0])\n",
    "        for i in range(0,6):\n",
    "            if(current_day_weather == weather_array[i]):\n",
    "                cweather_num=i\n",
    "        if(cweather_num==np.nan):\n",
    "            raise \n",
    "        print(cweather_num)\n",
    "          \n",
    "                \n",
    "        # Your implementation here\n",
    "        \n",
    "mymark=Markov()\n",
    "mymark.get_prob('sunny','rainy')"
   ]
  },
  {
   "cell_type": "code",
   "execution_count": null,
   "metadata": {},
   "outputs": [],
   "source": []
  },
  {
   "cell_type": "code",
   "execution_count": null,
   "metadata": {},
   "outputs": [],
   "source": []
  },
  {
   "cell_type": "code",
   "execution_count": null,
   "metadata": {},
   "outputs": [],
   "source": []
  },
  {
   "cell_type": "code",
   "execution_count": null,
   "metadata": {},
   "outputs": [],
   "source": []
  }
 ],
 "metadata": {
  "kernelspec": {
   "display_name": "Python 3",
   "language": "python",
   "name": "python3"
  },
  "language_info": {
   "codemirror_mode": {
    "name": "ipython",
    "version": 3
   },
   "file_extension": ".py",
   "mimetype": "text/x-python",
   "name": "python",
   "nbconvert_exporter": "python",
   "pygments_lexer": "ipython3",
   "version": "3.8.3"
  }
 },
 "nbformat": 4,
 "nbformat_minor": 4
}
